### Overview of Exception Handling in C++

Exception handling in C++ is a robust mechanism that allows you to manage errors and unexpected conditions in a structured way. It separates the error-handling code from the regular code, making your programs easier to write and maintain.

#### `try`, `catch`, and `throw` Statements

- **`try` Block**: 
  The `try` block contains the code that might throw an exception. If an exception occurs within this block, it will immediately stop executing, and control will pass to the corresponding `catch` block.

  ```cpp
  try {
      // Code that might throw an exception
  }
  ```

- **`throw` Statement**:
  The `throw` statement is used to signal the occurrence of an exceptional condition (an error) within a `try` block. It creates an exception object, which is then passed to the `catch` block that handles it.

  ```cpp
  throw std::runtime_error("An error occurred");
  ```

- **`catch` Block**: 
  The `catch` block is used to handle exceptions that are thrown in the associated `try` block. It specifies the type of exception it can handle, and when a matching exception is thrown, the `catch` block is executed.

  ```cpp
  catch (const std::runtime_error& e) {
      // Code to handle the exception
      std::cout << e.what() << std::endl;
  }
  ```

### Rethrowing an Exception

Rethrowing an exception allows you to propagate an exception that has been caught in a `catch` block further up the call stack. This is useful when you want to perform some local handling (like logging or cleanup) but still allow the exception to be managed by a higher-level function.

#### Rethrowing the Current Exception

When you catch an exception, you can rethrow it using the `throw;` statement. This does not modify the exception object; it simply passes the same exception further up the stack.

Here's an example:

```cpp
#include <iostream>
#include <stdexcept>

void function1() {
    try {
        throw std::runtime_error("An error occurred in function1");
    } catch (const std::runtime_error& e) {
        std::cout << "Caught in function1: " << e.what() << std::endl;
        throw; // Rethrow the same exception
    }
}

void function2() {
    try {
        function1();
    } catch (const std::runtime_error& e) {
        std::cout << "Caught in function2: " << e.what() << std::endl;
    }
}

int main() {
    function2();
    return 0;
}
```

**Explanation**:
- In `function1`, an exception is thrown and caught. After some handling (e.g., logging), the exception is rethrown using `throw;`.
- In `function2`, the rethrown exception from `function1` is caught and handled.

**Output**:
```
Caught in function1: An error occurred in function1
Caught in function2: An error occurred in function1
```

**Key Points**:
- **Propagation**: The `throw;` statement allows the current exception to be caught by another `catch` block higher up the call stack.
- **Exception Object**: The original exception object remains unchanged, preserving all its details.
- **Multiple Catch Blocks**: An exception can be rethrown and handled by another block in the same function or by a function higher up in the call stack.

#### Throwing a New Exception

Sometimes, instead of rethrowing the same exception, you might want to throw a different one. This is useful when you want to add more context or translate the caught exception into another type.

Example:

```cpp
#include <iostream>
#include <stdexcept>

void function1() {
    try {
        throw std::runtime_error("Original error");
    } catch (const std::runtime_error& e) {
        std::cout << "Caught in function1: " << e.what() << std::endl;
        throw std::logic_error("Translated error"); // Throw a different exception
    }
}

void function2() {
    try {
        function1();
    } catch (const std::logic_error& e) {
        std::cout << "Caught in function2: " << e.what() << std::endl;
    }
}

int main() {
    function2();
    return 0;
}
```

**Explanation**:
- In `function1`, a `std::runtime_error` is caught, but instead of rethrowing it, a new `std::logic_error` is thrown.
- In `function2`, the `std::logic_error` is caught and handled.

**Output**:
```
Caught in function1: Original error
Caught in function2: Translated error
```

### Use Cases for Rethrowing Exceptions

1. **Partial Handling**: You may want to handle part of the exception, like logging or cleanup, while allowing a higher-level function to manage the main logic.

2. **Context Addition**: Rethrowing an exception as a different type allows you to add more context or information, which might be useful for debugging or error reporting.

3. **Error Propagation**: Rethrowing ensures that the error can be caught and handled by a higher-level function, which might have a broader view of the program’s logic and how to resolve the issue.

### Conclusion

Rethrowing exceptions in C++ provides a flexible way to manage errors in complex applications. By allowing you to either propagate the original exception or throw a new one with added context, C++ gives you the tools to handle errors effectively at the appropriate level of your program’s logic.